Workbook

Sheet Anleitung
B2: Titel | C2: MatchZeit
B3: Urheber | C3: Claudia Bäuerlein
B4: Kontakt | C4: matchzeit@gmail.com
B5: Idee | C5: Das Tool ermöglicht die passende Software zur Arbeitszeiterfassung für Ihren Landwirtschaftlichen Betrieb zu finden.
C6: Die hinterlegte Datengrundlage kann mithilfe des Tabellenblatts "Programme_Grunddaten" jederzeit ergänzt und aktualisiert werden.
C7: Auf der Tool-Website werden dem Nutzer Fragen zu seinen individuellen Voraussetzungen und Bedürfnissen im Betrieb gestellt.
C8: Dem Matching von Nutzerantwort und Programm-Kriterium liegt ein Bewertungsscore zugrunde, der die
C9: maximal erreichbaren Punkte mit den erreichten Punkten in prozentualen Zusammenhang bringt.
C10: Nach einer Auswahl von max. 3 KO-Kriterien, werden als Ergebnis die drei passendsten Arbeitszeiterfassungssoftware angezeigt.
C11: Hier erhält der Nutzer Informationen und einen Link, der direkt auf die Unternehmenswebsite führt.
B12: Zielgruppe | C12: landwirtschaftliche Betriebe in Deutschland, die Arbeitszeiterfassung digitalisieren wollen
B13: Anleitung | C13: Datenpfleger | D13: Das Tabellenblatt "Programme_Grunddaten" aufrufen. Anweisungen dort folgen.
D14: Die anderen Tabellenblätter sind schreibgeschützt und werden für die Tool-Logik benötigt.
C15: Nutzer | D15: Link zum Tool anklicken, Erklärungen folgen
B16: Link zum Tool | C16: www.match-zeit.de

Sheet Programme_Grunddaten
A1: Titel | B1: Stammdaten und Bewertungsbasis
A2: Verantwortliche Person: | B2: Claudia Bäuerlein
A3: letzte Aktualisierung: | B3: 46178
A4: kurze Anleitung: | B4: Erfassen Sie hier neue Programme oder aktualisieren Sie bestehende Einträge.
B5: Bitte tragen Sie alle verfügbaren Informationen ein und bewerten Sie die Kriterien ausschließlich anhand der vorgegebenen Auswahlmöglichkeiten.
B6: Nutzen Sie die Kommentare in den Spaltenüberschriften als Orientierung für eine einheitliche Bewertung.
B7: Aktualisieren Sie den Bearbeitungsstatus nach Abschluss der Bearbeitung.
H8: Kriterium_ID | I8: K01 | J8: K02 | K8: K02.1 | L8: K02.1.1 | M8: K03 | N8: K04 | O8: K04.1 | P8: K04.2 | Q8: K05 | R8: K05.1 | S8: K06 | T8: K06.1 | U8: K06.2 | V8: K06.3 | W8: K07 | X8: K08 | Y8: K08.1 | Z8: K08.2 | AA8: K09 | AB8: K10 | AC8: K10.1 | AD8: K10.2 | AE8: K10.3 | AF8: K10.4 | AG8: K10.5 | AH8: K10.6 | AI8: K10.7 | AJ8: K11 | AK8: K12 | AL8: K13 | AM8: K14 | AN8: K15 | AO8: K16 | AP8: K17 | AQ8: K18 | AR8: K19 | AS8: K20 | AT8: K21 | AU8: K22 | AV8: K23 | AW8: K24 | AX8: K25
A9: Bearbeitungsstatus | B9: Programm_ID | C9: Programm_Name | D9: Anbieter | E9: Website | F9: Zielgruppe | G9: Kurzbeschreibung | H9: Kriterien | I9: open Source | J9: kommerziell (proprietär) | K9: kostenlose Version verfügbar | L9: Kostenmodell | M9: lokale Lösung (on-premise) | N9: cloud-/webbasiert | O9: Serverstandort, Hosting | P9: offline fähig (nachträgliche Synchronisation) | Q9: Erweiterbarkeit | R9: Schnittstelle zu DATEV | S9: Erfassungsmedium | T9: Smartphone (Browser, App) | U9: PC (webbasiert oder lokal installiert) | V9: Terminal | W9: EuGH konform | X9: Stand Alone Zeiterfassungsprogramm | Y9: Teil von HR-Programm | Z9: Teil von FMS | AA9: Zeiterfassung - Softwareaufbau | AB9: Zusatz- Features | AC9: Schichtplanung | AD9: Zutrittskontrolle | AE9: eAU | AF9: Urlaubsplanung | AG9: Personalakte | AH9: Arbeitszeitkonto | AI9: Tätigkeit- / Projekterfassung | AJ9: Anpassbarkeit | AK9: Sprachen | AL9: manuelle Eingabe | AM9: vollautomatisch (georeferenziert) | AN9: Geofencing | AO9: Bedien- und Zugriffsstruktur | AP9: Mandantenfähig | AQ9: Supportstruktur | AR9: Übersicht zur Datenauswertung | AS9: Korrekturen möglich | AT9: gesetzl. Pausen automatisch buchen | AU9: Überprüfung Arbeitszeitregeln / Pausenzeiten | AV9: Datenarchivierung | AW9: Besonderheiten | AX9: Preis | AY9: zuletzt geprüft am | AZ9: geprüft von | BA9: Kommentar
A10: Geprüft | B10: P01 | C10: Atoss | D10: ATOSS Software SE | E10: www.atoss.com | F10: alle Branchen | G10: digitales Workforce Management System | I10: Nein | J10: Ja | K10: Nein | M10: Nein | N10: Ja | Q10: offene Schnittstellen | R10: Ja | S10: App, Telefon, Terminal | T10: Ja | V10: Ja | W10: Ja | Y10: Ja | Z10: Nein | AB10: Ja | AC10: Ja | AF10: Ja | AG10: Ja | AI10: Ja | AK10: Deutsch, Englisch und andere | AL10: Ja | AM10: Nein | AQ10: Ja | AR10: Ja | AX10: keine Angabe | AY10: 46099 | AZ10: Claudia Bäuerlein
A11: Geprüft | B11: P02 | C11: ZEUS | D11: ISGUS GmbH | E11: www.isgus.de | F11: alle Branchen | G11: digitales Workforce Management System, mit Zeiterfassungsmodul | I11: Nein | J11: Ja | K11: Nein | M11: Nein | N11: Ja | O11: Deutschland | P11: Ja | Q11: offene Schnittstellen | R11: Ja | S11: App, Smartphone, Tablet, PC Terminal | T11: Ja | U11: Ja | V11: Ja | W11: Ja | Y11: Ja | Z11: Nein | AA11: modular | AB11: Ja | AC11: Ja | AD11: Ja | AF11: Ja | AG11: Ja | AH11: Ja | AI11: Ja | AK11: Deutsch und Englisch | AL11: Ja | AM11: Nein | AO11: rollenbasiert | AQ11: Ja | AR11: Ja | AS11: Ja | AU11: Ja | AW11: die Schichtbörse bietet den Mitarbeitern die Möglichkeit ihre Schichten digital zu tauschen, Evakuierungsübersicht: verspricht einen klaren Überblick über den Sicherheitsstatus der Mitarbeiter in kritischen Situationen, Open Source Teile des Codes sind verfügbar | AX11: keine Angabe | AY11: 46176 | AZ11: Claudia Bäuerlein
A12: Geprüft | B12: P03 | C12: GRÜN ZICOM | D12: GRÜN Software Group GmbH | E12: www.gruen.net | F12: Medien, Handel, Industrie | G12: Branchensoftware für Mittelstand | I12: Nein | J12: Ja | K12: Nein | L12: Abo / befristete Lizenz | M12: Ja | N12: Ja | P12: Ja | Q12: offene Schnittstellen | R12: Ja | S12: App, PC, Terminal | T12: Ja | U12: Ja | V12: Ja | W12: Ja | Y12: Ja | Z12: Nein | AA12: modular | AB12: Ja | AC12: Ja | AF12: Ja | AH12: Ja | AI12: Ja | AK12: Deutsch | AL12: Ja | AM12: Nein | AQ12: Ja | AR12: Ja | AS12: Ja | AX12: keine Angabe | AY12: 46100 | AZ12: Claudia Bäuerlein
A13: Geprüft | B13: P04 | C13: KRUTEC | D13: Krutec SoftCon GmbH | E13: www.krutec.de | F13: alle Branchen | G13: Fokus auf Zeiterfassung | I13: Nein | J13: Ja | K13: Nein | M13: Ja | N13: Ja | O13: Deutschland | Q13: offene Schnittstellen | R13: Ja | S13: Browser, App, Terminal | T13: Ja | U13: Ja | V13: Ja | W13: Ja | Y13: Ja | Z13: Nein | AA13: modular | AB13: Ja | AC13: Ja | AD13: Ja | AF13: Ja | AH13: Ja | AI13: Ja | AK13: Deutsch | AL13: Ja | AM13: Nein | AO13: rollenbasiert | AP13: Ja | AQ13: Ja | AR13: Ja | AS13: Ja | AU13: Ja | AW13: Standort bei Erfassung kann mit erfasst werden | AX13: keine Angabe | AY13: 46100 | AZ13: Claudia Bäuerlein
A14: Geprüft | B14: P05 | C14: meg, TiMaS | D14: mess-elektronik-groß GmbH | E14: www.megzeit.de | F14: Unternehmen, Behörden, Kleinbetrieb | G14: einfach, Arbeitszeiten erfassen, Zutritt steuern | I14: Nein | J14: Ja | K14: Nein | L14: einmalige Zahlung | M14: Ja | N14: Ja | O14: Deutschland | P14: Ja | Q14: offene Schnittstellen | R14: Ja | S14: App, Terminal, PC | T14: Ja | U14: Ja | V14: Ja | X14: Ja | Z14: Nein | AA14: modular | AB14: Ja | AD14: Ja | AF14: Ja | AH14: Ja | AI14: Ja | AK14: Deutsch und Englisch | AL14: Ja | AM14: Nein | AO14: rollenbasiert | AQ14: Ja | AR14: Ja | AS14: Ja | AW14: Standort bei Erfassung kann mit erfasst werden | AX14: z.B. Zeiterfassungssystem am Computer und per App einmalig 479 €, ab 10 Nutzern | AY14: 46101 | AZ14: Claudia Bäuerlein
A15: Geprüft | B15: P06 | C15: MobilZeit | D15: MobilZeit GmbH | E15: www.mobilzeit.de | F15: Handwerker, Dienstleistungsunternehmen | G15: Zeiterfassung, GPS-Ortung und Zutrittskontrolle | I15: Nein | J15: Ja | K15: Nein | M15: Nein | N15: Ja | Q15: offene Schnittstellen | R15: Ja | S15: App, Terminal, Box im Fahrzeug | T15: Ja | V15: Ja | X15: Ja | Z15: Nein | AA15: modular | AB15: Ja | AD15: Ja | AI15: Ja | AK15: Deutsch | AL15: Ja | AM15: Nein | AO15: rollenbasiert | AQ15: Ja | AR15: Ja | AW15: GPS Fahrzeugortung, zusätzliche Erfassung der Fahrzeugdaten z.B. Zündung An/Aus | AX15: keine Angabe | AY15: 46104 | AZ15: Claudia Bäuerlein
A16: Geprüft | B16: P07 | C16: Atoria, tisoware | D16: Atoria – the people software GmbH | E16: https://atoria-software.com/de, www.tisoware.com | F16: kleiner bis größerer Mittelstand | G16: modulare HR-Lösungen und Security Anwendungen | I16: Nein | J16: Ja | K16: Nein | L16: Abo / befristete Lizenz | M16: Nein | N16: Ja | Q16: offene Schnittstellen | R16: Ja | S16: App, PC, Terminal | T16: Ja | U16: Ja | V16: Ja | W16: Ja | Y16: Ja | Z16: Nein | AA16: modular | AB16: Ja | AC16: Ja | AD16: Ja | AE16: Ja | AF16: Ja | AG16: Ja | AI16: Ja | AL16: Ja | AM16: Nein | AO16: rollenbasiert | AQ16: Ja | AR16: Ja | AS16: Ja | AU16: Ja | AW16: bietet stationäre Terminals in Kooperation mit Praxispartnern an | AX16: Basismodell: 4 € / Nutzer / Monat | AY16: 46108 | AZ16: Claudia Bäuerlein
A17: Geprüft | B17: P08 | C17: venabo | D17: emvion Business Software GmbH | E17: www.venabo.de | F17: kleine und mittlere Unternehmen | G17: Zeiterfassung und IT-Service-Management | I17: Nein | J17: Ja | K17: Nein | L17: Abo / befristete Lizenz | M17: Nein | N17: Ja | P17: Ja | Q17: offene Schnittstellen | R17: Ja | S17: App, PC, Terminal | T17: Ja | U17: Ja | V17: Ja | W17: Ja | X17: Ja | Z17: Nein | AA17: modular | AB17: Ja | AC17: Ja | AD17: Ja | AE17: Ja | AF17: Ja | AG17: Ja | AI17: Ja | AK17: Deutsch, Englisch und andere | AL17: Ja | AM17: Nein | AO17: rollenbasiert | AQ17: Ja | AR17: Ja | AU17: Ja | AV17: revisionssicher mit Historienprotokoll | AW17: mit GPS Option, bietet stationäre Terminals in Kooperation mit Praxispartnern an | AX17: Beispielpaket für Landwirtschaft und Agrarhandel für 4,5 € / Nutzer / Monat | AY17: 46108 | AZ17: Claudia Bäuerlein
A18: Geprüft | B18: P09 | C18: ZMI. | D18: ZMI GmbH | E18: www.zmi.de | F18: kleine und mittlere Unternehmen, Konzern | G18: Zeiterfassung und HR | I18: Nein | J18: Ja | K18: Nein | M18: Ja | N18: Ja | O18: Deutschland | P18: Ja | Q18: offene Schnittstellen | R18: Ja | S18: App, PC, Terminal | T18: Ja | U18: Ja | V18: Ja | W18: Ja | X18: Ja | Z18: Nein | AA18: modular | AB18: Ja | AC18: Ja | AD18: Ja | AF18: Ja | AG18: Ja | AI18: Ja | AK18: Deutsch und Englisch | AL18: Ja | AM18: Nein | AO18: rollenbasiert | AP18: Ja | AQ18: Ja | AR18: Ja | AS18: Ja | AW18: bietet stationäre Terminals in Kooperation mit Praxispartnern an, Standort bei Erfassung kann mit erfasst werden | AX18: keine Angabe | AY18: 46108 | AZ18: Claudia Bäuerlein
A19: Geprüft | B19: P10 | C19: clockin | D19: clockin GmbH | E19: www.clockin.de | F19: Außendienst oder zuhause; Handwerker, Pflegekräfte und Vertriebsmitarbeiter | G19: einfache Zeiterfassung | I19: Nein | J19: Ja | K19: Nein | L19: Abo / befristete Lizenz | M19: Nein | N19: Ja | P19: Ja | Q19: offene Schnittstellen | R19: Ja | S19: App, PC | T19: Ja | U19: Ja | W19: Ja | X19: Ja | Z19: Nein | AA19: modular | AB19: Ja | AC19: Ja | AF19: Ja | AG19: Ja | AI19: Ja | AK19: Deutsch, Englisch und andere | AL19: Ja | AM19: Nein | AO19: rollenbasiert | AQ19: Ja | AR19: Ja | AS19: Ja | AU19: Ja | AW19: Standort bei Erfassung kann mit erfasst werden | AX19: Basismodell: 3,99 € / Nutzer / Monat | AY19: 46108 | AZ19: Claudia Bäuerlein
A20: Geprüft | B20: P11 | C20: clocko:do | D20: Clockodo GmbH | E20: www.clockodo.com | F20: alle Branchen | G20: einfache Zeiterfassung | I20: Nein | J20: Ja | K20: Nein | M20: Nein | N20: Ja | O20: Deutschland | P20: Ja | Q20: offene Schnittstellen | S20: App, PC | T20: Ja | U20: Ja | W20: Ja | Y20: Ja | Z20: Nein | AB20: Ja | AF20: Ja | AI20: Ja | AJ20: individuell programmierbar | AK20: Deutsch, Englisch und andere | AL20: Ja | AM20: Nein | AO20: rollenbasiert | AQ20: Ja | AR20: Ja | AS20: Ja | AU20: Ja | AW20: Über die API-Schnittstelle können Sie bei Bedarf Clockodo noch weiter nach Ihren Wünschen anpassen, mit Budgetüberwachung für Projekte, keine Anbindung an DATEV, aber vielen anderen Lohnbuchhaltungssystemen | AX20: Basismodell: 4 € / Nutzer / Monat | AY20: 46112 | AZ20: Claudia Bäuerlein
A21: Geprüft | B21: P12 | C21: Crewmeister | D21: ATOSS Aloud GmbH | E21: www.crewmeister.com | F21: alle Branchen | G21: Zeiterfassung: digital und zuverlässig | I21: Nein | J21: Ja | K21: Nein | L21: Abo / befristete Lizenz | M21: Ja | N21: Nein | O21: Deutschland | P21: Ja | Q21: offene Schnittstellen | R21: Ja | S21: App, PC | T21: Ja | U21: Ja | W21: Ja | X21: Ja | Z21: Nein | AA21: modular | AB21: Ja | AC21: Ja | AF21: Ja | AI21: Ja | AK21: Deutsch und Englisch | AL21: Ja | AM21: Nein | AO21: rollenbasiert | AQ21: Ja | AR21: Ja | AS21: Ja | AT21: Ja | AU21: Ja | AW21: GPS Erfassung möglich, Terminalmodus: standard PC / Tablet wird zu vollwertigem Zeiterfassungsterminal, umfangreiches Supportangebot | AX21: Basismodell: ab 1,5 € / Monat / Nutzer, bei jährlicher Abrechnung | AY21: 46112 | AZ21: Claudia Bäuerlein
A22: Geprüft | B22: P13 | C22: edtime | D22: eurodata AG | E22: www.ed-portal.de, https://www.edtime.de/ | F22: alle Branchen | G22: Personaleinsatzplanung und Zeiterfassung | I22: Nein | J22: Ja | K22: Nein | L22: Abo / befristete Lizenz | M22: Nein | N22: Ja | O22: Deutschland | Q22: offene Schnittstellen | S22: App, PC | T22: Ja | U22: Ja | W22: Ja | X22: Ja | Z22: Nein | AA22: modular | AB22: Ja | AC22: Ja | AE22: Ja | AF22: Ja | AK22: Deutsch | AL22: Ja | AM22: Nein | AO22: rollenbasiert | AQ22: Ja | AR22: Ja | AS22: Ja | AU22: Ja | AW22: GPS Standort kann bei Stempelung mit erfasst werden | AX22: 2,25 € / Monat / Mitarbeiter, Preis für jeden weiteren Mitarbeiter bei Kauf des Basispakets für 22,50 € / Monat inklusive 10 Mitarbeiter, Preis exklusive MwSt. | AY22: 46113 | AZ22: Claudia Bäuerlein
A23: Geprüft | B23: P14 | C23: HeavenHR 2.0 | D23: HeavenHR GmbH | E23: www.heavenhr.com | F23: kleine und mittlere Unternehmen | G23: Personalverwaltung und Echtzeit-Lohnabrechnung | I23: Nein | J23: Ja | K23: Nein | L23: Abo / befristete Lizenz | M23: Nein | N23: Ja | O23: Deutschland | Q23: offene Schnittstellen | S23: App, PC, Terminal | T23: Ja | U23: Ja | V23: Ja | Y23: Ja | Z23: Nein | AA23: modular | AB23: Ja | AF23: Ja | AG23: Ja | AK23: Deutsch und Englisch | AL23: Ja | AM23: Nein | AO23: rollenbasiert | AQ23: Ja | AR23: Ja | AS23: Ja | AV23: revisionssicher mit Historienprotokoll | AW23: Fokus liegt auf Lohnabrechnung | AX23: Modell mit Arbeitszeiterfassung: 5,5 € / Monat / Nutzer, Mindestpreis von 99 € | AY23: 46113 | AZ23: Claudia Bäuerlein
A24: Geprüft | B24: P15 | C24: prima:Time | D24: primatime.com s.r.o. | E24: www.primaerp.com | F24: Unternehmen oder Projektgruppen | G24: Projektmanagementsystem | I24: Nein | J24: Ja | K24: Nein | L24: Abo / befristete Lizenz | M24: Nein | N24: Ja | Q24: offene Schnittstellen | S24: App, PC | T24: Ja | U24: Ja | X24: Ja | Z24: Nein | AA24: modular | AB24: Ja | AI24: Ja | AK24: Deutsch, Englisch und andere | AL24: Ja | AM24: Nein | AO24: rollenbasiert | AQ24: Ja | AR24: Ja | AS24: Ja | AW24: Fokus auf Projektmanagement, besonders geeignet bei immer gleichen Stundenzahlen oder sich wiederholenden Aufgaben | AX24: Basismodell: 1,99 € / Monat / Nutzer, Preis ohne MwSt. | AY24: 46113 | AZ24: Claudia Bäuerlein
A25: Geprüft | B25: P16 | C25: TimeTell | D25: TimeTell B.V. | E25: www.timetell.de | F25: alle Branchen | G25: Software für Zeiterfassung und Planung | I25: Nein | J25: Ja | K25: Nein | L25: Abo / befristete Lizenz | M25: Nein | N25: Ja | Q25: offene Schnittstellen | R25: Ja | S25: App, PC, Terminal | T25: Ja | U25: Ja | V25: Ja | Y25: Ja | Z25: Nein | AA25: modular | AB25: Ja | AC25: Ja | AD25: Ja | AF25: Ja | AI25: Ja | AK25: Deutsch, Englisch und andere | AL25: Ja | AM25: Nein | AN25: Ja | AO25: rollenbasiert | AQ25: Ja | AR25: Ja | AW25: Geofencing beim An- und Abmelden (Mitarbeiter können sich nur in vorher definierten Bereich für Arbeit an- und abmelden) | AX25: Basismodell: einmalig 75 € + 3 € / Monat / Nutzer, ab 10 Nutzern | AY25: 46085 | AZ25: Claudia Bäuerlein
A26: Geprüft | B26: P17 | C26: REINER SCT timeCard | D26: REINER Kartengeräte GmbH und Co. KG | E26: www.timecard.de (reiner-sct), https://www.reiner-sct.com/timecard/ | F26: alle Branchen | G26: Zeiterfassung | I26: Nein | J26: Ja | K26: Nein | M26: Nein | N26: Ja | Q26: offene Schnittstellen | R26: Ja | S26: App, PC, Terminal | T26: Ja | U26: Ja | V26: Ja | W26: Ja | X26: Ja | Z26: Nein | AA26: modular | AB26: Ja | AD26: Ja | AE26: Ja | AF26: Ja | AI26: Ja | AK26: Deutsch und Englisch | AL26: Ja | AM26: Nein | AO26: rollenbasiert | AQ26: Ja | AX26: keine Angabe | AY26: 46085 | AZ26: Claudia Bäuerlein
A27: Geprüft | B27: P18 | C27: TIME&BILL | D27: Grobmeier Solutions GmbH | E27: www.timeandbill.de | F27: alle Branchen, kleinere Unternehmen und Teams | G27: einfache Zeiterfassung | I27: Ja | J27: Ja | K27: Nein | L27: Abo / befristete Lizenz | M27: Nein | N27: Ja | O27: Deutschland | Q27: offene Schnittstellen | S27: App, PC | T27: Ja | U27: Ja | X27: Ja | Z27: Nein | AA27: modular | AB27: Ja | AI27: Ja | AJ27: individuell programmierbar | AK27: Deutsch und Englisch | AL27: Ja | AM27: Nein | AO27: rollenbasiert | AQ27: Ja | AS27: Ja | AW27: bietet eine Open Source Variante | AX27: 5 € / Monat für 1 Benutzer, 15 € / Monat für bis zu 5 Benutzer, 40 € / Monat für bis zu 20 Benutzer | AY27: 46085 | AZ27: Claudia Bäuerlein
A28: Geprüft | B28: P19 | C28: timetac | D28: TimeTac GmbH | E28: www.timetac.com | F28: alle Branchen | G28: Zeiterfassung modular nach Unternehmensgröße | I28: Nein | J28: Ja | K28: Nein | L28: Abo / befristete Lizenz | M28: Nein | N28: Ja | O28: EU | P28: Ja | Q28: offene Schnittstellen | R28: Ja | S28: App, PC, Terminal | T28: Ja | U28: Ja | V28: Ja | W28: Ja | X28: Ja | Z28: Nein | AA28: modular | AB28: Ja | AF28: Ja | AI28: Ja | AK28: Deutsch, Englisch und andere | AL28: Ja | AM28: Nein | AO28: rollenbasiert | AQ28: Ja | AW28: Standort bei Erfassung kann mit erfasst werden, Verwaltung verschiedener Unternehmensstandorte möglich | AX28: Basismodell: 6,2 € / Monat / Nutzer + Basisgebühr + Nutzungsgebühr Module | AY28: 46120 | AZ28: Claudia Bäuerlein
A29: Geprüft | B29: P20 | C29: timr | D29: troii Software GmbH | E29: www.timr.com | F29: alle Branchen | G29: digitale Zeiterfassung | I29: Nein | J29: Ja | K29: Ja | L29: Abo / befristete Lizenz | M29: Nein | N29: Ja | O29: Deutschland | S29: App, PC, Terminal | T29: Ja | U29: Ja | V29: Ja | W29: Ja | X29: Ja | Z29: Nein | AA29: modular | AB29: Ja | AF29: Ja | AH29: Ja | AI29: Ja | AK29: Deutsch, Englisch und andere | AL29: Ja | AM29: Nein | AN29: Ja | AO29: rollenbasiert | AQ29: Ja | AR29: Ja | AT29: Ja | AU29: Ja | AW29: Standort bei Erfassung kann mit erfasst werden, Geofencing, freie Version für nur einen Benutzer | AX29: 1 Nutzer ist gratis | AY29: 46120 | AZ29: Claudia Bäuerlein
A30: Geprüft | B30: P21 | C30: Simple WebApps | D30: Harald Hornung | E30: www.simple-webapps.de | F30: kleine und mittelständige Organisationen | G30: basic Zeiterfassung | I30: Nein | J30: Ja | K30: Nein | L30: Abo / befristete Lizenz | M30: Ja | N30: Nein | Q30: offene Schnittstellen | R30: Ja | S30: Browser, Terminal | U30: Ja | V30: Ja | X30: Ja | Z30: Nein | AA30: modular | AB30: Ja | AC30: Ja | AF30: Ja | AI30: Ja | AL30: Ja | AM30: Nein | AQ30: Ja | AW30: Design der Software kann an die des Unternehmens angepasst werden (Corporate Design) | AX30: keine Angabe | AY30: 46120 | AZ30: Claudia Bäuerlein
A31: Geprüft | B31: P22 | C31: Personizer | D31: Personizer GmbH & Co. KG | E31: https://www.personizer.com/de | F31: Unternehmen und Organisationen | G31: einfache Zeiterfassung | I31: Nein | J31: Ja | K31: Nein | L31: Abo / befristete Lizenz | M31: Ja | N31: Nein | O31: EU | Q31: offene Schnittstellen | R31: Ja | S31: App, (PWA), Browser | T31: Ja | U31: Ja | W31: Ja | X31: Ja | Z31: Nein | AA31: modular | AB31: Ja | AE31: Ja | AF31: Ja | AG31: Ja | AH31: Ja | AI31: Ja | AK31: Deutsch und Englisch | AL31: Ja | AM31: Nein | AO31: rollenbasiert | AQ31: Ja | AR31: Ja | AS31: Ja | AV31: revisionssicher mit Historienprotokoll | AW31: Design der Software kann an die des Unternehmens angepasst werden (Corporate Design) | AX31: Basismodell Zeiterfassung: 3,7 € / Monat / Nutzer | AY31: 46120 | AZ31: Claudia Bäuerlein
A32: Geprüft | B32: P23 | C32: AGRARMONITOR | D32: betriko GmbH | E32: www.betriko.de | F32: Agrarmonitor, Lohnunternehmen, Ackerbau | G32: Dokumentation der Ackerarbeiten | I32: Nein | J32: Ja | K32: Nein | L32: Abo / befristete Lizenz | M32: Nein | N32: Ja | O32: Deutschland | Q32: offene Schnittstellen | R32: Ja | S32: App, Smartphone, Tablet | T32: Ja | U32: Ja | Z32: Ja | AA32: monolithisch | AB32: Ja | AF32: Ja | AI32: Ja | AK32: Deutsch | AL32: Ja | AM32: Nein | AO32: rollenbasiert | AQ32: Ja | AW32: umfassende Agrarmanagementsoftware | AX32: 2.900 € jährlich oder 29 € / Monat / aktivem Gerät | AY32: 46204 | AZ32: Claudia Bäuerlein
A33: Geprüft | B33: P24 | C33: askDANTE | D33: askDANTE systems GmbH | E33: https://www.askdante.com/ | F33: kleine und mittlere Unternehmen | G33: einfache Zeiterfassung | I33: Nein | J33: Ja | K33: Ja | L33: Abo / befristete Lizenz | M33: Nein | N33: Ja | Q33: offene Schnittstellen | R33: Ja | S33: App, PC, Terminal | T33: Ja | U33: Ja | V33: Ja | W33: Ja | X33: Ja | Z33: Nein | AA33: modular | AB33: Ja | AC33: Ja | AE33: Ja | AF33: Ja | AG33: Ja | AI33: Ja | AL33: Ja | AM33: Nein | AQ33: Ja | AU33: Ja | AW33: große Auswahl an Alarmregeln: von Arbeitszeitüberschreitung bis Dienstjubiläum | AX33: bis zu 5 Nutzer kostenfrei, dann 4,5 € / Monat / Nutzer | AY33: 46120 | AZ33: Claudia Bäuerlein
A34: Geprüft | B34: P25 | C34: agroprojekt | D34: agroproject Technologie- und Informationssysteme GmbH & Co.KG | E34: www.agroproject.de | F34: Landwirte, Betriebe mit Saisonarbeitskräften | G34: FMS mit integrierter Zeiterfassung insbesondere für Saisonarbeitskräfte | I34: Nein | J34: Ja | M34: Ja | N34: Nein | Q34: offene Schnittstellen | R34: Ja | S34: Mobilgeräte, Terminal | T34: Ja | V34: Ja | Z34: Ja | AA34: modular | AB34: Ja | AG34: Ja | AK34: Deutsch | AL34: Ja | AM34: Nein | AO34: rollenbasiert | AQ34: Ja | AR34: Ja | AW34: Standort bei Erfassung kann mit erfasst werden, Erntehelferverwaltung, Ackerschlagkartei mit Spracheingabe | AY34: 46204 | AZ34: Claudia Bäuerlein
A35: Geprüft | B35: P26 | C35: WorkingHours | D35: Timo Partl | E35: https://workinghoursapp.com/de | F35: alle Branchen | G35: einfache Zeiterfassungsapp | I35: Nein | J35: Ja | K35: Ja | M35: Nein | N35: Ja | Q35: offene Schnittstellen | S35: App | T35: Ja | X35: Ja | Z35: Nein | AA35: monolithisch | AB35: Ja | AI35: Ja | AL35: Ja | AM35: Ja | AN35: Ja | AO35: Einzelzugang | AR35: Ja | AW35: Daten werden im persönlichen Cloudspeicher gespeichert, GPS-Arbeitsplatzerkennung: Timer startet, wenn man zur Arbeit kommt, Geofencing | AX35: keine Angabe | AY35: 46121 | AZ35: Claudia Bäuerlein
A36: Geprüft | B36: P27 | C36: Kelio | D36: KELIO GmbH | E36: https://www.kelio.de/ | F36: alle Branchen | G36: Workforce management software | I36: Nein | J36: Ja | K36: Nein | M36: Ja | N36: Nein | Q36: offene Schnittstellen | S36: webbasiert, Browser, Terminal | U36: Ja | V36: Ja | Y36: Ja | Z36: Nein | AA36: modular | AB36: Ja | AC36: Ja | AD36: Ja | AF36: Ja | AH36: Ja | AI36: Ja | AK36: Deutsch, Englisch und andere | AL36: Ja | AM36: Nein | AQ36: Ja | AR36: Ja | AS36: Ja | AU36: Ja | AW36: Verwaltung mehrerer Unternehmen und Standorte | AX36: keine Angabe | AY36: 46121 | AZ36: Claudia Bäuerlein
A37: Geprüft | B37: P28 | C37: Personio | D37: Personio SE & Co. KG | E37: https://www.personio.de/ | F37: alle Branchen | G37: HR und Lohnbuchhaltung | I37: Nein | J37: Ja | L37: Abo / befristete Lizenz | M37: Nein | Q37: offene Schnittstellen | R37: Ja | S37: App, Terminal | T37: Ja | V37: Ja | Y37: Ja | Z37: Nein | AA37: modular | AB37: Ja | AG37: Ja | AK37: Deutsch, Englisch und andere | AL37: Ja | AM37: Nein | AQ37: Ja | AR37: Ja | AS37: Ja | AU37: Ja | AW37: umfassende HR-Management Software, mit KI Assistent | AX37: keine Angabe | AY37: 46121 | AZ37: Claudia Bäuerlein
A38: Geprüft | B38: P29 | C38: AIDA ORGA | D38: AIDA ORGA | E38: https://aida-orga.de/de/ | F38: alle Branchen | G38: HR- und Workforce Management | I38: Nein | J38: Ja | M38: Nein | N38: Ja | O38: Deutschland | Q38: offene Schnittstellen | R38: Ja | S38: App, Browser, Terminal, Terminalmodus | T38: Ja | U38: Ja | V38: Ja | W38: Ja | Y38: Ja | Z38: Nein | AA38: modular | AB38: Ja | AC38: Ja | AD38: Ja | AF38: Ja | AG38: Ja | AI38: Ja | AL38: Ja | AM38: Nein | AO38: rollenbasiert | AQ38: Ja | AR38: Ja | AS38: Ja | AV38: revisionssicher mit Historienprotokoll | AX38: keine Angabe | AY38: 46121 | AZ38: Claudia Bäuerlein
A39: Geprüft | B39: P30 | C39: Time 3010, Access 3010, PEP 3010, Peris 3010 | D39: AZS System AG | E39: https://azs.de/ | F39: alle Branchen | G39: Lösungen für Zeiterfassung, Zutrittskontrolle und Personaleinsatzplanung | I39: Nein | J39: Ja | K39: Nein | M39: Ja | N39: Ja | Q39: offene Schnittstellen | R39: Ja | S39: App, Browser, Terminal | T39: Ja | U39: Ja | V39: Ja | X39: Ja | Z39: Nein | AA39: modular | AB39: Ja | AC39: Ja | AD39: Ja | AE39: Ja | AF39: Ja | AG39: Ja | AK39: Deutsch und Englisch | AL39: Ja | AM39: Nein | AO39: rollenbasiert | AQ39: Ja | AR39: Ja | AS39: Ja | AX39: keine Angabe | AY39: 46121 | AZ39: Claudia Bäuerlein
A40: Geprüft | B40: P31 | C40: poool | D40: Poool Software & Consulting GmbH | E40: https://www.poool.cc/ | F40: alle Branchen, Schwerpunkt Dienstleistungsunternehmen | G40: ERP-Software | I40: Nein | J40: Ja | K40: Nein | L40: Abo / befristete Lizenz | M40: Nein | N40: Ja | O40: EU | Q40: offene Schnittstellen | R40: Ja | S40: App, PC | T40: Ja | U40: Ja | Y40: Ja | Z40: Nein | AA40: modular | AB40: Ja | AF40: Ja | AG40: Ja | AI40: Ja | AK40: Deutsch und Englisch | AL40: Ja | AM40: Nein | AO40: rollenbasiert | AQ40: Ja | AR40: Ja | AU40: Ja | AW40: ERP-Software mit Fokus auf Dienstleistungsunternehmen | AX40: Basislizenz: 99 € / Monat | AY40: 46121 | AZ40: Claudia Bäuerlein
...

Sheet programme_info
A1: programm_id | B1: programm_name | C1: anbieter | D1: website | E1: kurzbeschreibung | F1: zielgruppe | G1: erfassungsmedium | H1: besonderheiten | I1: preis
A2: =IF(AND(Programme_Grunddaten!$A10="Geprüft",Programme_Grunddaten!B10<>""),Programme_Grunddaten!B10,"") -> P01 | B2: =IF(AND(Programme_Grunddaten!$A10="Geprüft",Programme_Grunddaten!C10<>""),Programme_Grunddaten!C10,"") -> Atoss | C2: =IF(AND(Programme_Grunddaten!$A10="Geprüft",Programme_Grunddaten!D10<>""),Programme_Grunddaten!D10,"") -> ATOSS Software SE | D2: =IF(AND(Programme_Grunddaten!$A10="Geprüft",Programme_Grunddaten!E10<>""),Programme_Grunddaten!E10,"") -> www.atoss.com | E2: =IF(AND(Programme_Grunddaten!$A10="Geprüft",Programme_Grunddaten!G10<>""),Programme_Grunddaten!G10,"") -> digitales Workforce Management System | F2: =IF(AND(Programme_Grunddaten!$A10="Geprüft",Programme_Grunddaten!F10<>""),Programme_Grunddaten!F10,"") -> alle Branchen | G2: =IF(AND(Programme_Grunddaten!$A10="Geprüft",Programme_Grunddaten!S10<>""),Programme_Grunddaten!S10,"") -> App, Telefon, Terminal | H2: =IF(AND(Programme_Grunddaten!$A10="Geprüft",Programme_Grunddaten!AW10<>""),Programme_Grunddaten!AW10,"") | I2: =IF(AND(Programme_Grunddaten!$A10="Geprüft",Programme_Grunddaten!AX10<>""),Programme_Grunddaten!AX10,"") -> keine Angabe | K2: =IF(AND(programme_info!A11="Geprüft",Programme_Grunddaten!AW10<>""),Programme_Grunddaten!AW10,"")
A3: =IF(AND(Programme_Grunddaten!$A11="Geprüft",Programme_Grunddaten!B11<>""),Programme_Grunddaten!B11,"") -> P02 | B3: =IF(AND(Programme_Grunddaten!$A11="Geprüft",Programme_Grunddaten!C11<>""),Programme_Grunddaten!C11,"") -> ZEUS | C3: =IF(AND(Programme_Grunddaten!$A11="Geprüft",Programme_Grunddaten!D11<>""),Programme_Grunddaten!D11,"") -> ISGUS GmbH | D3: =IF(AND(Programme_Grunddaten!$A11="Geprüft",Programme_Grunddaten!E11<>""),Programme_Grunddaten!E11,"") -> www.isgus.de | E3: =IF(AND(Programme_Grunddaten!$A11="Geprüft",Programme_Grunddaten!G11<>""),Programme_Grunddaten!G11,"") -> digitales Workforce Management System, mit Zeiterfassungsmodul | F3: =IF(AND(Programme_Grunddaten!$A11="Geprüft",Programme_Grunddaten!F11<>""),Programme_Grunddaten!F11,"") -> alle Branchen | G3: =IF(AND(Programme_Grunddaten!$A11="Geprüft",Programme_Grunddaten!S11<>""),Programme_Grunddaten!S11,"") -> App, Smartphone, Tablet, PC Terminal | H3: =IF(AND(Programme_Grunddaten!$A11="Geprüft",Programme_Grunddaten!AW11<>""),Programme_Grunddaten!AW11,"") -> die Schichtbörse bietet den Mitarbeitern die Möglichkeit ihre Schichten digital zu tauschen, Evakuierungsübersicht: verspricht einen klaren Überblick über den Sicherheitsstatus der Mitarbeiter in kritischen Situationen, Open Source Teile des Codes sind verfügbar | I3: =IF(AND(Programme_Grunddaten!$A11="Geprüft",Programme_Grunddaten!AX11<>""),Programme_Grunddaten!AX11,"") -> keine Angabe
A4: =IF(AND(Programme_Grunddaten!$A12="Geprüft",Programme_Grunddaten!B12<>""),Programme_Grunddaten!B12,"") -> P03 | B4: =IF(AND(Programme_Grunddaten!$A12="Geprüft",Programme_Grunddaten!C12<>""),Programme_Grunddaten!C12,"") -> GRÜN ZICOM | C4: =IF(AND(Programme_Grunddaten!$A12="Geprüft",Programme_Grunddaten!D12<>""),Programme_Grunddaten!D12,"") -> GRÜN Software Group GmbH | D4: =IF(AND(Programme_Grunddaten!$A12="Geprüft",Programme_Grunddaten!E12<>""),Programme_Grunddaten!E12,"") -> www.gruen.net | E4: =IF(AND(Programme_Grunddaten!$A12="Geprüft",Programme_Grunddaten!G12<>""),Programme_Grunddaten!G12,"") -> Branchensoftware für Mittelstand | F4: =IF(AND(Programme_Grunddaten!$A12="Geprüft",Programme_Grunddaten!F12<>""),Programme_Grunddaten!F12,"") -> Medien, Handel, Industrie | G4: =IF(AND(Programme_Grunddaten!$A12="Geprüft",Programme_Grunddaten!S12<>""),Programme_Grunddaten!S12,"") -> App, PC, Terminal | H4: =IF(AND(Programme_Grunddaten!$A12="Geprüft",Programme_Grunddaten!AW12<>""),Programme_Grunddaten!AW12,"") | I4: =IF(AND(Programme_Grunddaten!$A12="Geprüft",Programme_Grunddaten!AX12<>""),Programme_Grunddaten!AX12,"") -> keine Angabe | K4: =IF(AND(programme_info!A13="Geprüft",Programme_Grunddaten!AW12<>""),Programme_Grunddaten!AW12,"")
A5: =IF(AND(Programme_Grunddaten!$A13="Geprüft",Programme_Grunddaten!B13<>""),Programme_Grunddaten!B13,"") -> P04 | B5: =IF(AND(Programme_Grunddaten!$A13="Geprüft",Programme_Grunddaten!C13<>""),Programme_Grunddaten!C13,"") -> KRUTEC | C5: =IF(AND(Programme_Grunddaten!$A13="Geprüft",Programme_Grunddaten!D13<>""),Programme_Grunddaten!D13,"") -> Krutec SoftCon GmbH | D5: =IF(AND(Programme_Grunddaten!$A13="Geprüft",Programme_Grunddaten!E13<>""),Programme_Grunddaten!E13,"") -> www.krutec.de | E5: =IF(AND(Programme_Grunddaten!$A13="Geprüft",Programme_Grunddaten!G13<>""),Programme_Grunddaten!G13,"") -> Fokus auf Zeiterfassung | F5: =IF(AND(Programme_Grunddaten!$A13="Geprüft",Programme_Grunddaten!F13<>""),Programme_Grunddaten!F13,"") -> alle Branchen | G5: =IF(AND(Programme_Grunddaten!$A13="Geprüft",Programme_Grunddaten!S13<>""),Programme_Grunddaten!S13,"") -> Browser, App, Terminal | H5: =IF(AND(Programme_Grunddaten!$A13="Geprüft",Programme_Grunddaten!AW13<>""),Programme_Grunddaten!AW13,"") -> Standort bei Erfassung kann mit erfasst werden | I5: =IF(AND(Programme_Grunddaten!$A13="Geprüft",Programme_Grunddaten!AX13<>""),Programme_Grunddaten!AX13,"") -> keine Angabe
A6: =IF(AND(Programme_Grunddaten!$A14="Geprüft",Programme_Grunddaten!B14<>""),Programme_Grunddaten!B14,"") -> P05 | B6: =IF(AND(Programme_Grunddaten!$A14="Geprüft",Programme_Grunddaten!C14<>""),Programme_Grunddaten!C14,"") -> meg, TiMaS | C6: =IF(AND(Programme_Grunddaten!$A14="Geprüft",Programme_Grunddaten!D14<>""),Programme_Grunddaten!D14,"") -> mess-elektronik-groß GmbH | D6: =IF(AND(Programme_Grunddaten!$A14="Geprüft",Programme_Grunddaten!E14<>""),Programme_Grunddaten!E14,"") -> www.megzeit.de | E6: =IF(AND(Programme_Grunddaten!$A14="Geprüft",Programme_Grunddaten!G14<>""),Programme_Grunddaten!G14,"") -> einfach, Arbeitszeiten erfassen, Zutritt steuern | F6: =IF(AND(Programme_Grunddaten!$A14="Geprüft",Programme_Grunddaten!F14<>""),Programme_Grunddaten!F14,"") -> Unternehmen, Behörden, Kleinbetrieb | G6: =IF(AND(Programme_Grunddaten!$A14="Geprüft",Programme_Grunddaten!S14<>""),Programme_Grunddaten!S14,"") -> App, Terminal, PC | H6: =IF(AND(Programme_Grunddaten!$A14="Geprüft",Programme_Grunddaten!AW14<>""),Programme_Grunddaten!AW14,"") -> Standort bei Erfassung kann mit erfasst werden | I6: =IF(AND(Programme_Grunddaten!$A14="Geprüft",Programme_Grunddaten!AX14<>""),Programme_Grunddaten!AX14,"") -> z.B. Zeiterfassungssystem am Computer und per App einmalig 479 €, ab 10 Nutzern
A7: =IF(AND(Programme_Grunddaten!$A15="Geprüft",Programme_Grunddaten!B15<>""),Programme_Grunddaten!B15,"") -> P06 | B7: =IF(AND(Programme_Grunddaten!$A15="Geprüft",Programme_Grunddaten!C15<>""),Programme_Grunddaten!C15,"") -> MobilZeit | C7: =IF(AND(Programme_Grunddaten!$A15="Geprüft",Programme_Grunddaten!D15<>""),Programme_Grunddaten!D15,"") -> MobilZeit GmbH | D7: =IF(AND(Programme_Grunddaten!$A15="Geprüft",Programme_Grunddaten!E15<>""),Programme_Grunddaten!E15,"") -> www.mobilzeit.de | E7: =IF(AND(Programme_Grunddaten!$A15="Geprüft",Programme_Grunddaten!G15<>""),Programme_Grunddaten!G15,"") -> Zeiterfassung, GPS-Ortung und Zutrittskontrolle | F7: =IF(AND(Programme_Grunddaten!$A15="Geprüft",Programme_Grunddaten!F15<>""),Programme_Grunddaten!F15,"") -> Handwerker, Dienstleistungsunternehmen | G7: =IF(AND(Programme_Grunddaten!$A15="Geprüft",Programme_Grunddaten!S15<>""),Programme_Grunddaten!S15,"") -> App, Terminal, Box im Fahrzeug | H7: =IF(AND(Programme_Grunddaten!$A15="Geprüft",Programme_Grunddaten!AW15<>""),Programme_Grunddaten!AW15,"") -> GPS Fahrzeugortung, zusätzliche Erfassung der Fahrzeugdaten z.B. Zündung An/Aus | I7: =IF(AND(Programme_Grunddaten!$A15="Geprüft",Programme_Grunddaten!AX15<>""),Programme_Grunddaten!AX15,"") -> keine Angabe
A8: =IF(AND(Programme_Grunddaten!$A16="Geprüft",Programme_Grunddaten!B16<>""),Programme_Grunddaten!B16,"") -> P07 | B8: =IF(AND(Programme_Grunddaten!$A16="Geprüft",Programme_Grunddaten!C16<>""),Programme_Grunddaten!C16,"") -> Atoria, tisoware | C8: =IF(AND(Programme_Grunddaten!$A16="Geprüft",Programme_Grunddaten!D16<>""),Programme_Grunddaten!D16,"") -> Atoria – the people software GmbH | D8: =IF(AND(Programme_Grunddaten!$A16="Geprüft",Programme_Grunddaten!E16<>""),Programme_Grunddaten!E16,"") -> https://atoria-software.com/de, www.tisoware.com | E8: =IF(AND(Programme_Grunddaten!$A16="Geprüft",Programme_Grunddaten!G16<>""),Programme_Grunddaten!G16,"") -> modulare HR-Lösungen und Security Anwendungen | F8: =IF(AND(Programme_Grunddaten!$A16="Geprüft",Programme_Grunddaten!F16<>""),Programme_Grunddaten!F16,"") -> kleiner bis größerer Mittelstand | G8: =IF(AND(Programme_Grunddaten!$A16="Geprüft",Programme_Grunddaten!S16<>""),Programme_Grunddaten!S16,"") -> App, PC, Terminal | H8: =IF(AND(Programme_Grunddaten!$A16="Geprüft",Programme_Grunddaten!AW16<>""),Programme_Grunddaten!AW16,"") -> bietet stationäre Terminals in Kooperation mit Praxispartnern an | I8: =IF(AND(Programme_Grunddaten!$A16="Geprüft",Programme_Grunddaten!AX16<>""),Programme_Grunddaten!AX16,"") -> Basismodell: 4 € / Nutzer / Monat
A9: =IF(AND(Programme_Grunddaten!$A17="Geprüft",Programme_Grunddaten!B17<>""),Programme_Grunddaten!B17,"") -> P08 | B9: =IF(AND(Programme_Grunddaten!$A17="Geprüft",Programme_Grunddaten!C17<>""),Programme_Grunddaten!C17,"") -> venabo | C9: =IF(AND(Programme_Grunddaten!$A17="Geprüft",Programme_Grunddaten!D17<>""),Programme_Grunddaten!D17,"") -> emvion Business Software GmbH | D9: =IF(AND(Programme_Grunddaten!$A17="Geprüft",Programme_Grunddaten!E17<>""),Programme_Grunddaten!E17,"") -> www.venabo.de | E9: =IF(AND(Programme_Grunddaten!$A17="Geprüft",Programme_Grunddaten!G17<>""),Programme_Grunddaten!G17,"") -> Zeiterfassung und IT-Service-Management | F9: =IF(AND(Programme_Grunddaten!$A17="Geprüft",Programme_Grunddaten!F17<>""),Programme_Grunddaten!F17,"") -> kleine und mittlere Unternehmen | G9: =IF(AND(Programme_Grunddaten!$A17="Geprüft",Programme_Grunddaten!S17<>""),Programme_Grunddaten!S17,"") -> App, PC, Terminal | H9: =IF(AND(Programme_Grunddaten!$A17="Geprüft",Programme_Grunddaten!AW17<>""),Programme_Grunddaten!AW17,"") -> mit GPS Option, bietet stationäre Terminals in Kooperation mit Praxispartnern an | I9: =IF(AND(Programme_Grunddaten!$A17="Geprüft",Programme_Grunddaten!AX17<>""),Programme_Grunddaten!AX17,"") -> Beispielpaket für Landwirtschaft und Agrarhandel für 4,5 € / Nutzer / Monat
A10: =IF(AND(Programme_Grunddaten!$A18="Geprüft",Programme_Grunddaten!B18<>""),Programme_Grunddaten!B18,"") -> P09 | B10: =IF(AND(Programme_Grunddaten!$A18="Geprüft",Programme_Grunddaten!C18<>""),Programme_Grunddaten!C18,"") -> ZMI. | C10: =IF(AND(Programme_Grunddaten!$A18="Geprüft",Programme_Grunddaten!D18<>""),Programme_Grunddaten!D18,"") -> ZMI GmbH | D10: =IF(AND(Programme_Grunddaten!$A18="Geprüft",Programme_Grunddaten!E18<>""),Programme_Grunddaten!E18,"") -> www.zmi.de | E10: =IF(AND(Programme_Grunddaten!$A18="Geprüft",Programme_Grunddaten!G18<>""),Programme_Grunddaten!G18,"") -> Zeiterfassung und HR | F10: =IF(AND(Programme_Grunddaten!$A18="Geprüft",Programme_Grunddaten!F18<>""),Programme_Grunddaten!F18,"") -> kleine und mittlere Unternehmen, Konzern | G10: =IF(AND(Programme_Grunddaten!$A18="Geprüft",Programme_Grunddaten!S18<>""),Programme_Grunddaten!S18,"") -> App, PC, Terminal | H10: =IF(AND(Programme_Grunddaten!$A18="Geprüft",Programme_Grunddaten!AW18<>""),Programme_Grunddaten!AW18,"") -> bietet stationäre Terminals in Kooperation mit Praxispartnern an, Standort bei Erfassung kann mit erfasst werden | I10: =IF(AND(Programme_Grunddaten!$A18="Geprüft",Programme_Grunddaten!AX18<>""),Programme_Grunddaten!AX18,"") -> keine Angabe
A11: =IF(AND(Programme_Grunddaten!$A19="Geprüft",Programme_Grunddaten!B19<>""),Programme_Grunddaten!B19,"") -> P10 | B11: =IF(AND(Programme_Grunddaten!$A19="Geprüft",Programme_Grunddaten!C19<>""),Programme_Grunddaten!C19,"") -> clockin | C11: =IF(AND(Programme_Grunddaten!$A19="Geprüft",Programme_Grunddaten!D19<>""),Programme_Grunddaten!D19,"") -> clockin GmbH | D11: =IF(AND(Programme_Grunddaten!$A19="Geprüft",Programme_Grunddaten!E19<>""),Programme_Grunddaten!E19,"") -> www.clockin.de | E11: =IF(AND(Programme_Grunddaten!$A19="Geprüft",Programme_Grunddaten!G19<>""),Programme_Grunddaten!G19,"") -> einfache Zeiterfassung | F11: =IF(AND(Programme_Grunddaten!$A19="Geprüft",Programme_Grunddaten!F19<>""),Programme_Grunddaten!F19,"") -> Außendienst oder zuhause; Handwerker, Pflegekräfte und Vertriebsmitarbeiter | G11: =IF(AND(Programme_Grunddaten!$A19="Geprüft",Programme_Grunddaten!S19<>""),Programme_Grunddaten!S19,"") -> App, PC | H11: =IF(AND(Programme_Grunddaten!$A19="Geprüft",Programme_Grunddaten!AW19<>""),Programme_Grunddaten!AW19,"") -> Standort bei Erfassung kann mit erfasst werden | I11: =IF(AND(Programme_Grunddaten!$A19="Geprüft",Programme_Grunddaten!AX19<>""),Programme_Grunddaten!AX19,"") -> Basismodell: 3,99 € / Nutzer / Monat
A12: =IF(AND(Programme_Grunddaten!$A20="Geprüft",Programme_Grunddaten!B20<>""),Programme_Grunddaten!B20,"") -> P11 | B12: =IF(AND(Programme_Grunddaten!$A20="Geprüft",Programme_Grunddaten!C20<>""),Programme_Grunddaten!C20,"") -> clocko:do | C12: =IF(AND(Programme_Grunddaten!$A20="Geprüft",Programme_Grunddaten!D20<>""),Programme_Grunddaten!D20,"") -> Clockodo GmbH | D12: =IF(AND(Programme_Grunddaten!$A20="Geprüft",Programme_Grunddaten!E20<>""),Programme_Grunddaten!E20,"") -> www.clockodo.com | E12: =IF(AND(Programme_Grunddaten!$A20="Geprüft",Programme_Grunddaten!G20<>""),Programme_Grunddaten!G20,"") -> einfache Zeiterfassung | F12: =IF(AND(Programme_Grunddaten!$A20="Geprüft",Programme_Grunddaten!F20<>""),Programme_Grunddaten!F20,"") -> alle Branchen | G12: =IF(AND(Programme_Grunddaten!$A20="Geprüft",Programme_Grunddaten!S20<>""),Programme_Grunddaten!S20,"") -> App, PC | H12: =IF(AND(Programme_Grunddaten!$A20="Geprüft",Programme_Grunddaten!AW20<>""),Programme_Grunddaten!AW20,"") -> Über die API-Schnittstelle können Sie bei Bedarf Clockodo noch weiter nach Ihren Wünschen anpassen, mit Budgetüberwachung für Projekte, keine Anbindung an DATEV, aber vielen anderen Lohnbuchhaltungssystemen | I12: =IF(AND(Programme_Grunddaten!$A20="Geprüft",Programme_Grunddaten!AX20<>""),Programme_Grunddaten!AX20,"") -> Basismodell: 4 € / Nutzer / Monat
A13: =IF(AND(Programme_Grunddaten!$A21="Geprüft",Programme_Grunddaten!B21<>""),Programme_Grunddaten!B21,"") -> P12 | B13: =IF(AND(Programme_Grunddaten!$A21="Geprüft",Programme_Grunddaten!C21<>""),Programme_Grunddaten!C21,"") -> Crewmeister | C13: =IF(AND(Programme_Grunddaten!$A21="Geprüft",Programme_Grunddaten!D21<>""),Programme_Grunddaten!D21,"") -> ATOSS Aloud GmbH | D13: =IF(AND(Programme_Grunddaten!$A21="Geprüft",Programme_Grunddaten!E21<>""),Programme_Grunddaten!E21,"") -> www.crewmeister.com | E13: =IF(AND(Programme_Grunddaten!$A21="Geprüft",Programme_Grunddaten!G21<>""),Programme_Grunddaten!G21,"") -> Zeiterfassung: digital und zuverlässig | F13: =IF(AND(Programme_Grunddaten!$A21="Geprüft",Programme_Grunddaten!F21<>""),Programme_Grunddaten!F21,"") -> alle Branchen | G13: =IF(AND(Programme_Grunddaten!$A21="Geprüft",Programme_Grunddaten!S21<>""),Programme_Grunddaten!S21,"") -> App, PC | H13: =IF(AND(Programme_Grunddaten!$A21="Geprüft",Programme_Grunddaten!AW21<>""),Programme_Grunddaten!AW21,"") -> GPS Erfassung möglich, Terminalmodus: standard PC / Tablet wird zu vollwertigem Zeiterfassungsterminal, umfangreiches Supportangebot | I13: =IF(AND(Programme_Grunddaten!$A21="Geprüft",Programme_Grunddaten!AX21<>""),Programme_Grunddaten!AX21,"") -> Basismodell: ab 1,5 € / Monat / Nutzer, bei jährlicher Abrechnung
A14: =IF(AND(Programme_Grunddaten!$A22="Geprüft",Programme_Grunddaten!B22<>""),Programme_Grunddaten!B22,"") -> P13 | B14: =IF(AND(Programme_Grunddaten!$A22="Geprüft",Programme_Grunddaten!C22<>""),Programme_Grunddaten!C22,"") -> edtime | C14: =IF(AND(Programme_Grunddaten!$A22="Geprüft",Programme_Grunddaten!D22<>""),Programme_Grunddaten!D22,"") -> eurodata AG | D14: =IF(AND(Programme_Grunddaten!$A22="Geprüft",Programme_Grunddaten!E22<>""),Programme_Grunddaten!E22,"") -> www.ed-portal.de, https://www.edtime.de/ | E14: =IF(AND(Programme_Grunddaten!$A22="Geprüft",Programme_Grunddaten!G22<>""),Programme_Grunddaten!G22,"") -> Personaleinsatzplanung und Zeiterfassung | F14: =IF(AND(Programme_Grunddaten!$A22="Geprüft",Programme_Grunddaten!F22<>""),Programme_Grunddaten!F22,"") -> alle Branchen | G14: =IF(AND(Programme_Grunddaten!$A22="Geprüft",Programme_Grunddaten!S22<>""),Programme_Grunddaten!S22,"") -> App, PC | H14: =IF(AND(Programme_Grunddaten!$A22="Geprüft",Programme_Grunddaten!AW22<>""),Programme_Grunddaten!AW22,"") -> GPS Standort kann bei Stempelung mit erfasst werden | I14: =IF(AND(Programme_Grunddaten!$A22="Geprüft",Programme_Grunddaten!AX22<>""),Programme_Grunddaten!AX22,"") -> 2,25 € / Monat / Mitarbeiter, Preis für jeden weiteren Mitarbeiter bei Kauf des Basispakets für 22,50 € / Monat inklusive 10 Mitarbeiter, Preis exklusive MwSt.
A15: =IF(AND(Programme_Grunddaten!$A23="Geprüft",Programme_Grunddaten!B23<>""),Programme_Grunddaten!B23,"") -> P14 | B15: =IF(AND(Programme_Grunddaten!$A23="Geprüft",Programme_Grunddaten!C23<>""),Programme_Grunddaten!C23,"") -> HeavenHR 2.0 | C15: =IF(AND(Programme_Grunddaten!$A23="Geprüft",Programme_Grunddaten!D23<>""),Programme_Grunddaten!D23,"") -> HeavenHR GmbH | D15: =IF(AND(Programme_Grunddaten!$A23="Geprüft",Programme_Grunddaten!E23<>""),Programme_Grunddaten!E23,"") -> www.heavenhr.com | E15: =IF(AND(Programme_Grunddaten!$A23="Geprüft",Programme_Grunddaten!G23<>""),Programme_Grunddaten!G23,"") -> Personalverwaltung und Echtzeit-Lohnabrechnung | F15: =IF(AND(Programme_Grunddaten!$A23="Geprüft",Programme_Grunddaten!F23<>""),Programme_Grunddaten!F23,"") -> kleine und mittlere Unternehmen | G15: =IF(AND(Programme_Grunddaten!$A23="Geprüft",Programme_Grunddaten!S23<>""),Programme_Grunddaten!S23,"") -> App, PC, Terminal | H15: =IF(AND(Programme_Grunddaten!$A23="Geprüft",Programme_Grunddaten!AW23<>""),Programme_Grunddaten!AW23,"") -> Fokus liegt auf Lohnabrechnung | I15: =IF(AND(Programme_Grunddaten!$A23="Geprüft",Programme_Grunddaten!AX23<>""),Programme_Grunddaten!AX23,"") -> Modell mit Arbeitszeiterfassung: 5,5 € / Monat / Nutzer, Mindestpreis von 99 €
A16: =IF(AND(Programme_Grunddaten!$A24="Geprüft",Programme_Grunddaten!B24<>""),Programme_Grunddaten!B24,"") -> P15 | B16: =IF(AND(Programme_Grunddaten!$A24="Geprüft",Programme_Grunddaten!C24<>""),Programme_Grunddaten!C24,"") -> prima:Time | C16: =IF(AND(Programme_Grunddaten!$A24="Geprüft",Programme_Grunddaten!D24<>""),Programme_Grunddaten!D24,"") -> primatime.com s.r.o. | D16: =IF(AND(Programme_Grunddaten!$A24="Geprüft",Programme_Grunddaten!E24<>""),Programme_Grunddaten!E24,"") -> www.primaerp.com | E16: =IF(AND(Programme_Grunddaten!$A24="Geprüft",Programme_Grunddaten!G24<>""),Programme_Grunddaten!G24,"") -> Projektmanagementsystem | F16: =IF(AND(Programme_Grunddaten!$A24="Geprüft",Programme_Grunddaten!F24<>""),Programme_Grunddaten!F24,"") -> Unternehmen oder Projektgruppen | G16: =IF(AND(Programme_Grunddaten!$A24="Geprüft",Programme_Grunddaten!S24<>""),Programme_Grunddaten!S24,"") -> App, PC | H16: =IF(AND(Programme_Grunddaten!$A24="Geprüft",Programme_Grunddaten!AW24<>""),Programme_Grunddaten!AW24,"") -> Fokus auf Projektmanagement, besonders geeignet bei immer gleichen Stundenzahlen oder sich wiederholenden Aufgaben | I16: =IF(AND(Programme_Grunddaten!$A24="Geprüft",Programme_Grunddaten!AX24<>""),Programme_Grunddaten!AX24,"") -> Basismodell: 1,99 € / Monat / Nutzer, Preis ohne MwSt.
... A122: =IF(AND(Programme_Grunddaten!$A130="Geprüft",Programme_Grunddaten!B130<>""),Programme_Grunddaten!B130,"") | B122: =IF(AND(Programme_Grunddaten!$A130="Geprüft",Programme_Grunddaten!C130<>""),Programme_Grunddaten!C130,"") | C122: =IF(AND(Programme_Grunddaten!$A130="Geprüft",Programme_Grunddaten!D130<>""),Programme_Grunddaten!D130,"") | D122: =IF(AND(Programme_Grunddaten!$A130="Geprüft",Programme_Grunddaten!E130<>""),Programme_Grunddaten!E130,"") | E122: =IF(AND(Programme_Grunddaten!$A130="Geprüft",Programme_Grunddaten!G130<>""),Programme_Grunddaten!G130,"") | F122: =IF(AND(Programme_Grunddaten!$A130="Geprüft",Programme_Grunddaten!F130<>""),Programme_Grunddaten!F130,"") | G122: =IF(AND(Programme_Grunddaten!$A130="Geprüft",Programme_Grunddaten!S130<>""),Programme_Grunddaten!S130,"") | H122: =IF(AND(Programme_Grunddaten!$A130="Geprüft",Programme_Grunddaten!AW130<>""),Programme_Grunddaten!AW130,"") | I122: =IF(AND(Programme_Grunddaten!$A130="Geprüft",Programme_Grunddaten!AX130<>""),Programme_Grunddaten!AX130,"")
A123: =IF(AND(Programme_Grunddaten!#REF!="Geprüft",Programme_Grunddaten!#REF!<>""),Programme_Grunddaten!#REF!,"") -> #REF! | B123: =IF(AND(Programme_Grunddaten!#REF!="Geprüft",Programme_Grunddaten!#REF!<>""),Programme_Grunddaten!#REF!,"") -> #REF! | C123: =IF(AND(Programme_Grunddaten!#REF!="Geprüft",Programme_Grunddaten!#REF!<>""),Programme_Grunddaten!#REF!,"") -> #REF! | D123: =IF(AND(Programme_Grunddaten!#REF!="Geprüft",Programme_Grunddaten!#REF!<>""),Programme_Grunddaten!#REF!,"") -> #REF! | E123: =IF(AND(Programme_Grunddaten!#REF!="Geprüft",Programme_Grunddaten!#REF!<>""),Programme_Grunddaten!#REF!,"") -> #REF! | F123: =IF(AND(Programme_Grunddaten!#REF!="Geprüft",Programme_Grunddaten!#REF!<>""),Programme_Grunddaten!#REF!,"") -> #REF! | G123: =IF(AND(Programme_Grunddaten!#REF!="Geprüft",Programme_Grunddaten!#REF!<>""),Programme_Grunddaten!#REF!,"") -> #REF! | H123: =IF(AND(Programme_Grunddaten!#REF!="Geprüft",Programme_Grunddaten!#REF!<>""),Programme_Grunddaten!#REF!,"") -> #REF! | I123: =IF(AND(Programme_Grunddaten!#REF!="Geprüft",Programme_Grunddaten!#REF!<>""),Programme_Grunddaten!#REF!,"") -> #REF!
A124: =IF(AND(Programme_Grunddaten!#REF!="Geprüft",Programme_Grunddaten!#REF!<>""),Programme_Grunddaten!#REF!,"") -> #REF! | B124: =IF(AND(Programme_Grunddaten!#REF!="Geprüft",Programme_Grunddaten!#REF!<>""),Programme_Grunddaten!#REF!,"") -> #REF! | C124: =IF(AND(Programme_Grunddaten!#REF!="Geprüft",Programme_Grunddaten!#REF!<>""),Programme_Grunddaten!#REF!,"") -> #REF! | D124: =IF(AND(Programme_Grunddaten!#REF!="Geprüft",Programme_Grunddaten!#REF!<>""),Programme_Grunddaten!#REF!,"") -> #REF! | E124: =IF(AND(Programme_Grunddaten!#REF!="Geprüft",Programme_Grunddaten!#REF!<>""),Programme_Grunddaten!#REF!,"") -> #REF! | F124: =IF(AND(Programme_Grunddaten!#REF!="Geprüft",Programme_Grunddaten!#REF!<>""),Programme_Grunddaten!#REF!,"") -> #REF! | G124: =IF(AND(Programme_Grunddaten!#REF!="Geprüft",Programme_Grunddaten!#REF!<>""),Programme_Grunddaten!#REF!,"") -> #REF! | H124: =IF(AND(Programme_Grunddaten!#REF!="Geprüft",Programme_Grunddaten!#REF!<>""),Programme_Grunddaten!#REF!,"") -> #REF! | I124: =IF(AND(Programme_Grunddaten!#REF!="Geprüft",Programme_Grunddaten!#REF!<>""),Programme_Grunddaten!#REF!,"") -> #REF!
A125: =IF(AND(Programme_Grunddaten!#REF!="Geprüft",Programme_Grunddaten!#REF!<>""),Programme_Grunddaten!#REF!,"") -> #REF! | B125: =IF(AND(Programme_Grunddaten!#REF!="Geprüft",Programme_Grunddaten!#REF!<>""),Programme_Grunddaten!#REF!,"") -> #REF! | C125: =IF(AND(Programme_Grunddaten!#REF!="Geprüft",Programme_Grunddaten!#REF!<>""),Programme_Grunddaten!#REF!,"") -> #REF! | D125: =IF(AND(Programme_Grunddaten!#REF!="Geprüft",Programme_Grunddaten!#REF!<>""),Programme_Grunddaten!#REF!,"") -> #REF! | E125: =IF(AND(Programme_Grunddaten!#REF!="Geprüft",Programme_Grunddaten!#REF!<>""),Programme_Grunddaten!#REF!,"") -> #REF! | F125: =IF(AND(Programme_Grunddaten!#REF!="Geprüft",Programme_Grunddaten!#REF!<>""),Programme_Grunddaten!#REF!,"") -> #REF! | G125: =IF(AND(Programme_Grunddaten!#REF!="Geprüft",Programme_Grunddaten!#REF!<>""),Programme_Grunddaten!#REF!,"") -> #REF! | H125: =IF(AND(Programme_Grunddaten!#REF!="Geprüft",Programme_Grunddaten!#REF!<>""),Programme_Grunddaten!#REF!,"") -> #REF! | I125: =IF(AND(Programme_Grunddaten!#REF!="Geprüft",Programme_Grunddaten!#REF!<>""),Programme_Grunddaten!#REF!,"") -> #REF!
A126: =IF(AND(Programme_Grunddaten!$A131="Geprüft",Programme_Grunddaten!B131<>""),Programme_Grunddaten!B131,"") | B126: =IF(AND(Programme_Grunddaten!$A131="Geprüft",Programme_Grunddaten!C131<>""),Programme_Grunddaten!C131,"") | C126: =IF(AND(Programme_Grunddaten!$A131="Geprüft",Programme_Grunddaten!D131<>""),Programme_Grunddaten!D131,"") | D126: =IF(AND(Programme_Grunddaten!$A131="Geprüft",Programme_Grunddaten!E131<>""),Programme_Grunddaten!E131,"") | E126: =IF(AND(Programme_Grunddaten!$A131="Geprüft",Programme_Grunddaten!G131<>""),Programme_Grunddaten!G131,"") | F126: =IF(AND(Programme_Grunddaten!$A131="Geprüft",Programme_Grunddaten!F131<>""),Programme_Grunddaten!F131,"") | G126: =IF(AND(Programme_Grunddaten!$A131="Geprüft",Programme_Grunddaten!S131<>""),Programme_Grunddaten!S131,"") | H126: =IF(AND(Programme_Grunddaten!$A131="Geprüft",Programme_Grunddaten!AW131<>""),Programme_Grunddaten!AW131,"") | I126: =IF(AND(Programme_Grunddaten!$A131="Geprüft",Programme_Grunddaten!AX131<>""),Programme_Grunddaten!AX131,"")
A127: =IF(AND(Programme_Grunddaten!$A132="Geprüft",Programme_Grunddaten!B132<>""),Programme_Grunddaten!B132,"") | B127: =IF(AND(Programme_Grunddaten!$A132="Geprüft",Programme_Grunddaten!C132<>""),Programme_Grunddaten!C132,"") | C127: =IF(AND(Programme_Grunddaten!$A132="Geprüft",Programme_Grunddaten!D132<>""),Programme_Grunddaten!D132,"") | D127: =IF(AND(Programme_Grunddaten!$A132="Geprüft",Programme_Grunddaten!E132<>""),Programme_Grunddaten!E132,"") | E127: =IF(AND(Programme_Grunddaten!$A132="Geprüft",Programme_Grunddaten!G132<>""),Programme_Grunddaten!G132,"") | F127: =IF(AND(Programme_Grunddaten!$A132="Geprüft",Programme_Grunddaten!F132<>""),Programme_Grunddaten!F132,"") | G127: =IF(AND(Programme_Grunddaten!$A132="Geprüft",Programme_Grunddaten!S132<>""),Programme_Grunddaten!S132,"") | H127: =IF(AND(Programme_Grunddaten!$A132="Geprüft",Programme_Grunddaten!AW132<>""),Programme_Grunddaten!AW132,"") | I127: =IF(AND(Programme_Grunddaten!$A132="Geprüft",Programme_Grunddaten!AX132<>""),Programme_Grunddaten!AX132,"")
A128: =IF(AND(Programme_Grunddaten!$A133="Geprüft",Programme_Grunddaten!B133<>""),Programme_Grunddaten!B133,"") | B128: =IF(AND(Programme_Grunddaten!$A133="Geprüft",Programme_Grunddaten!C133<>""),Programme_Grunddaten!C133,"") | C128: =IF(AND(Programme_Grunddaten!$A133="Geprüft",Programme_Grunddaten!D133<>""),Programme_Grunddaten!D133,"") | D128: =IF(AND(Programme_Grunddaten!$A133="Geprüft",Programme_Grunddaten!E133<>""),Programme_Grunddaten!E133,"") | E128: =IF(AND(Programme_Grunddaten!$A133="Geprüft",Programme_Grunddaten!G133<>""),Programme_Grunddaten!G133,"") | F128: =IF(AND(Programme_Grunddaten!$A133="Geprüft",Programme_Grunddaten!F133<>""),Programme_Grunddaten!F133,"") | G128: =IF(AND(Programme_Grunddaten!$A133="Geprüft",Programme_Grunddaten!S133<>""),Programme_Grunddaten!S133,"") | H128: =IF(AND(Programme_Grunddaten!$A133="Geprüft",Programme_Grunddaten!AW133<>""),Programme_Grunddaten!AW133,"") | I128: =IF(AND(Programme_Grunddaten!$A133="Geprüft",Programme_Grunddaten!AX133<>""),Programme_Grunddaten!AX133,"")
A129: =IF(AND(Programme_Grunddaten!$A134="Geprüft",Programme_Grunddaten!B134<>""),Programme_Grunddaten!B134,"") | B129: =IF(AND(Programme_Grunddaten!$A134="Geprüft",Programme_Grunddaten!C134<>""),Programme_Grunddaten!C134,"") | C129: =IF(AND(Programme_Grunddaten!$A134="Geprüft",Programme_Grunddaten!D134<>""),Programme_Grunddaten!D134,"") | D129: =IF(AND(Programme_Grunddaten!$A134="Geprüft",Programme_Grunddaten!E134<>""),Programme_Grunddaten!E134,"") | E129: =IF(AND(Programme_Grunddaten!$A134="Geprüft",Programme_Grunddaten!G134<>""),Programme_Grunddaten!G134,"") | F129: =IF(AND(Programme_Grunddaten!$A134="Geprüft",Programme_Grunddaten!F134<>""),Programme_Grunddaten!F134,"") | G129: =IF(AND(Programme_Grunddaten!$A134="Geprüft",Programme_Grunddaten!S134<>""),Programme_Grunddaten!S134,"") | H129: =IF(AND(Programme_Grunddaten!$A134="Geprüft",Programme_Grunddaten!AW134<>""),Programme_Grunddaten!AW134,"") | I129: =IF(AND(Programme_Grunddaten!$A134="Geprüft",Programme_Grunddaten!AX134<>""),Programme_Grunddaten!AX134,"")
A130: =IF(AND(Programme_Grunddaten!$A135="Geprüft",Programme_Grunddaten!B135<>""),Programme_Grunddaten!B135,"") | B130: =IF(AND(Programme_Grunddaten!$A135="Geprüft",Programme_Grunddaten!C135<>""),Programme_Grunddaten!C135,"") | C130: =IF(AND(Programme_Grunddaten!$A135="Geprüft",Programme_Grunddaten!D135<>""),Programme_Grunddaten!D135,"") | D130: =IF(AND(Programme_Grunddaten!$A135="Geprüft",Programme_Grunddaten!E135<>""),Programme_Grunddaten!E135,"") | E130: =IF(AND(Programme_Grunddaten!$A135="Geprüft",Programme_Grunddaten!G135<>""),Programme_Grunddaten!G135,"") | F130: =IF(AND(Programme_Grunddaten!$A135="Geprüft",Programme_Grunddaten!F135<>""),Programme_Grunddaten!F135,"") | G130: =IF(AND(Programme_Grunddaten!$A135="Geprüft",Programme_Grunddaten!S135<>""),Programme_Grunddaten!S135,"") | H130: =IF(AND(Programme_Grunddaten!$A135="Geprüft",Programme_Grunddaten!AW135<>""),Programme_Grunddaten!AW135,"") | I130: =IF(AND(Programme_Grunddaten!$A135="Geprüft",Programme_Grunddaten!AX135<>""),Programme_Grunddaten!AX135,"")
A131: =IF(AND(Programme_Grunddaten!$A136="Geprüft",Programme_Grunddaten!B136<>""),Programme_Grunddaten!B136,"") | B131: =IF(AND(Programme_Grunddaten!$A136="Geprüft",Programme_Grunddaten!C136<>""),Programme_Grunddaten!C136,"") | C131: =IF(AND(Programme_Grunddaten!$A136="Geprüft",Programme_Grunddaten!D136<>""),Programme_Grunddaten!D136,"") | D131: =IF(AND(Programme_Grunddaten!$A136="Geprüft",Programme_Grunddaten!E136<>""),Programme_Grunddaten!E136,"") | E131: =IF(AND(Programme_Grunddaten!$A136="Geprüft",Programme_Grunddaten!G136<>""),Programme_Grunddaten!G136,"") | F131: =IF(AND(Programme_Grunddaten!$A136="Geprüft",Programme_Grunddaten!F136<>""),Programme_Grunddaten!F136,"") | G131: =IF(AND(Programme_Grunddaten!$A136="Geprüft",Programme_Grunddaten!S136<>""),Programme_Grunddaten!S136,"") | H131: =IF(AND(Programme_Grunddaten!$A136="Geprüft",Programme_Grunddaten!AW136<>""),Programme_Grunddaten!AW136,"") | I131: =IF(AND(Programme_Grunddaten!$A136="Geprüft",Programme_Grunddaten!AX136<>""),Programme_Grunddaten!AX136,"")
A132: =IF(AND(Programme_Grunddaten!$A137="Geprüft",Programme_Grunddaten!B137<>""),Programme_Grunddaten!B137,"") | B132: =IF(AND(Programme_Grunddaten!$A137="Geprüft",Programme_Grunddaten!C137<>""),Programme_Grunddaten!C137,"") | C132: =IF(AND(Programme_Grunddaten!$A137="Geprüft",Programme_Grunddaten!D137<>""),Programme_Grunddaten!D137,"") | D132: =IF(AND(Programme_Grunddaten!$A137="Geprüft",Programme_Grunddaten!E137<>""),Programme_Grunddaten!E137,"") | E132: =IF(AND(Programme_Grunddaten!$A137="Geprüft",Programme_Grunddaten!G137<>""),Programme_Grunddaten!G137,"") | F132: =IF(AND(Programme_Grunddaten!$A137="Geprüft",Programme_Grunddaten!F137<>""),Programme_Grunddaten!F137,"") | G132: =IF(AND(Programme_Grunddaten!$A137="Geprüft",Programme_Grunddaten!S137<>""),Programme_Grunddaten!S137,"") | H132: =IF(AND(Programme_Grunddaten!$A137="Geprüft",Programme_Grunddaten!AW137<>""),Programme_Grunddaten!AW137,"") | I132: =IF(AND(Programme_Grunddaten!$A137="Geprüft",Programme_Grunddaten!AX137<>""),Programme_Grunddaten!AX137,"")
A133: =IF(AND(Programme_Grunddaten!$A138="Geprüft",Programme_Grunddaten!B138<>""),Programme_Grunddaten!B138,"") | B133: =IF(AND(Programme_Grunddaten!$A138="Geprüft",Programme_Grunddaten!C138<>""),Programme_Grunddaten!C138,"") | C133: =IF(AND(Programme_Grunddaten!$A138="Geprüft",Programme_Grunddaten!D138<>""),Programme_Grunddaten!D138,"") | D133: =IF(AND(Programme_Grunddaten!$A138="Geprüft",Programme_Grunddaten!E138<>""),Programme_Grunddaten!E138,"") | E133: =IF(AND(Programme_Grunddaten!$A138="Geprüft",Programme_Grunddaten!G138<>""),Programme_Grunddaten!G138,"") | F133: =IF(AND(Programme_Grunddaten!$A138="Geprüft",Programme_Grunddaten!F138<>""),Programme_Grunddaten!F138,"") | G133: =IF(AND(Programme_Grunddaten!$A138="Geprüft",Programme_Grunddaten!S138<>""),Programme_Grunddaten!S138,"") | H133: =IF(AND(Programme_Grunddaten!$A138="Geprüft",Programme_Grunddaten!AW138<>""),Programme_Grunddaten!AW138,"") | I133: =IF(AND(Programme_Grunddaten!$A138="Geprüft",Programme_Grunddaten!AX138<>""),Programme_Grunddaten!AX138,"")
A134: =IF(AND(Programme_Grunddaten!$A139="Geprüft",Programme_Grunddaten!B139<>""),Programme_Grunddaten!B139,"") | B134: =IF(AND(Programme_Grunddaten!$A139="Geprüft",Programme_Grunddaten!C139<>""),Programme_Grunddaten!C139,"") | C134: =IF(AND(Programme_Grunddaten!$A139="Geprüft",Programme_Grunddaten!D139<>""),Programme_Grunddaten!D139,"") | D134: =IF(AND(Programme_Grunddaten!$A139="Geprüft",Programme_Grunddaten!E139<>""),Programme_Grunddaten!E139,"") | E134: =IF(AND(Programme_Grunddaten!$A139="Geprüft",Programme_Grunddaten!G139<>""),Programme_Grunddaten!G139,"") | F134: =IF(AND(Programme_Grunddaten!$A139="Geprüft",Programme_Grunddaten!F139<>""),Programme_Grunddaten!F139,"") | G134: =IF(AND(Programme_Grunddaten!$A139="Geprüft",Programme_Grunddaten!S139<>""),Programme_Grunddaten!S139,"") | H134: =IF(AND(Programme_Grunddaten!$A139="Geprüft",Programme_Grunddaten!AW139<>""),Programme_Grunddaten!AW139,"") | I134: =IF(AND(Programme_Grunddaten!$A139="Geprüft",Programme_Grunddaten!AX139<>""),Programme_Grunddaten!AX139,"")
